Workbook

Sheet Avaliação
A1: ID Avaliação | B1: Data da avaliação | C1: Operação | D1: Processo avaliado | E1: Nome_Documento | F1: Quantidade | G1: Existe? | H1: Está atualizado? | I1: Última atualização | J1: Padronizado? | K1: Coforme? | L1: Existência | M1: Atualização | N1: Padrão | O1: Conformidade | P1: Documentação | Q1: Geral | R1: Observação | S1: Plano de Ação | T1: Responsável | U1: Prazo | V1: Status da Ação
A2: =IF(B2="","",ROW()-4) | B2: 46245 | C2: PROCESSOS | D2: Política | E2: Politica da informação Documentada | F2: 1 | G2: SIM | H2: SIM | I2: 45682 | J2: SIM | K2: Não Conformidade Grave | L2: =IF(G2="","",IF(G2="SIM",1,0)) | M2: =IF(H2="","",IF(H2="SIM",1,0)) | N2: =IF(J2="","",IF(J2="SIM",1,0)) | O2: =IF(K2="","",IF(K2="Conformidade",1,IF(K2="Não conformidade",0,IF(K2="Não conformidade grave",-1,"")))) | P2: =IF(COUNTA(G2,H2,J2,K2)=0,"",ROUND(AVERAGE(L2:O2)*100,0)) | Q2: =IFERROR(AVERAGEIF(C$2:C$57,C2,P$2:P$57),"N/A")
A3: =IF(B3="","",ROW()-4) | B3: 46245 | C3: PROCESSOS | D3: Procedimento Operacional | E3: ORIENTAR QUANTO A TRATATIVA DE SOLICITAÇÕES À AREA DE PROCESSOS COMPARTILHADO | F3: 1 | G3: SIM | H3: SIM | I3: 45672 | J3: SIM | K3: Não Conformidade Grave | L3: =IF(G3="","",IF(G3="SIM",1,0)) | M3: =IF(H3="","",IF(H3="SIM",1,0)) | N3: =IF(J3="","",IF(J3="SIM",1,0)) | O3: =IF(K3="","",IF(K3="Conformidade",1,IF(K3="Não conformidade",0,IF(K3="Não conformidade grave",-1,"")))) | P3: =IF(COUNTA(G3,H3,J3)=0,"",ROUND(AVERAGE(L3:O3)*100,0)) | Q3: =IFERROR(AVERAGEIF(C$2:C$57,C3,P$2:P$57),"N/A")
A4: =IF(B4="","",ROW()-4) | B4: 46245 | C4: PROCESSOS | D4: Procedimento Operacional | E4: ORIENTAR QUANTO A APROVAÇÃO DE DOCUMENTOS EM DBM | F4: 1 | G4: SIM | H4: NÃO | I4: 45672 | J4: SIM | K4: Não Conformidade Grave | L4: =IF(G4="","",IF(G4="SIM",1,0)) | M4: =IF(H4="","",IF(H4="SIM",1,0)) | N4: =IF(J4="","",IF(J4="SIM",1,0)) | O4: =IF(K4="","",IF(K4="Conformidade",1,IF(K4="Não conformidade",0,IF(K4="Não conformidade grave",-1,"")))) | P4: =IF(COUNTA(G4,H4,J4)=0,"",ROUND(AVERAGE(L4:O4)*100,0)) | Q4: =IFERROR(AVERAGEIF(C$2:C$57,C4,P$2:P$57),"N/A")
A5: =IF(B5="","",ROW()-4) | B5: 46245 | C5: Qualidade | D5: Política | E5: Politica da informação Documentada | F5: 1 | G5: NÃO | H5: SIM | I5: 45682 | J5: NÃO | K5: Não Conformidade Grave | L5: =IF(G5="","",IF(G5="SIM",1,0)) | M5: =IF(H5="","",IF(H5="SIM",1,0)) | N5: =IF(J5="","",IF(J5="SIM",1,0)) | O5: =IF(K5="","",IF(K5="Conformidade",1,IF(K5="Não conformidade",0,IF(K5="Não conformidade grave",-1,"")))) | P5: =IF(COUNTA(G5,H5,J5)=0,"",ROUND(AVERAGE(L5:O5)*100,0)) | Q5: =IFERROR(AVERAGEIF(C$2:C$57,C5,P$2:P$57),"N/A")
A6: =IF(B6="","",ROW()-4) | B6: 46245 | C6: Qualidade | D6: Procedimento Operacional | E6: ORIENTAR QUANTO A TRATATIVA DE SOLICITAÇÕES À AREA DE PROCESSOS COMPARTILHADO | F6: 1 | G6: SIM | H6: SIM | I6: 45672 | J6: SIM | K6: Não Conformidade Grave | L6: =IF(G6="","",IF(G6="SIM",1,0)) | M6: =IF(H6="","",IF(H6="SIM",1,0)) | N6: =IF(J6="","",IF(J6="SIM",1,0)) | O6: =IF(K6="","",IF(K6="Conformidade",1,IF(K6="Não conformidade",0,IF(K6="Não conformidade grave",-1,"")))) | P6: =IF(COUNTA(G6,H6,J6)=0,"",ROUND(AVERAGE(L6:O6)*100,0)) | Q6: =IFERROR(AVERAGEIF(C$2:C$57,C6,P$2:P$57),"N/A")
A7: =IF(B7="","",ROW()-4) | B7: 46245 | C7: Qualidade | D7: Procedimento Operacional | E7: ORIENTAR QUANTO A APROVAÇÃO DE DOCUMENTOS EM DBM | F7: 1 | G7: SIM | H7: SIM | I7: 45672 | J7: SIM | K7: Não Conformidade Grave | L7: =IF(G7="","",IF(G7="SIM",1,0)) | M7: =IF(H7="","",IF(H7="SIM",1,0)) | N7: =IF(J7="","",IF(J7="SIM",1,0)) | O7: =IF(K7="","",IF(K7="Conformidade",1,IF(K7="Não conformidade",0,IF(K7="Não conformidade grave",-1,"")))) | P7: =IF(COUNTA(G7,H7,J7,K7)=0,"",ROUND(AVERAGE(L7:O7)*100,0)) | Q7: =IFERROR(AVERAGEIF(C$2:C$57,C7,P$2:P$57),"N/A")
A8: =IF(B8="","",ROW()-4) | B8: 46178 | C8: PROCESSOS | D8: Admissão | E8: Política de Segurança da Informação | F8: 1 | G8: NÃO | H8: NÃO | I8: 45294 | J8: NÃO | K8: Não Conformidade Grave | L8: =IF(G8="","",IF(G8="SIM",1,0)) | M8: =IF(H8="","",IF(H8="SIM",1,0)) | N8: =IF(J8="","",IF(J8="SIM",1,0)) | O8: =IF(K8="","",IF(K8="Conformidade",1,IF(K8="Não Conformidade",0,IF(K8="Não Conformidade Grave",-1,"")))) | P8: =IF(COUNTA(G8,H8,J8,K8)=0,"",ROUND(AVERAGE(L8:O8)*100,0)) | Q8: =IFERROR(AVERAGEIF(C$2:C$57,C8,P$2:P$57),"N/A") | R8: Foi identificada oportunidade de adequação documental. | S8: Criar documento e obter aprovação | T8: Ana Lima | U8: 46270 | V8: Não iniciado
A9: =IF(B9="","",ROW()-4) | B9: 46209 | C9: Qualidade | D9: Gestão de Contratos | E9: Fluxo de Aprovação de Compras | F9: 2 | G9: SIM | H9: SIM | I9: 45692 | J9: SIM | K9: Conformidade | L9: =IF(G9="","",IF(G9="SIM",1,0)) | M9: =IF(H9="","",IF(H9="SIM",1,0)) | N9: =IF(J9="","",IF(J9="SIM",1,0)) | O9: =IF(K9="","",IF(K9="Conformidade",1,IF(K9="Não Conformidade",0,IF(K9="Não Conformidade Grave",-1,"")))) | P9: =IF(COUNTA(G9,H9,J9,K9)=0,"",ROUND(AVERAGE(L9:O9)*100,0)) | Q9: =IFERROR(AVERAGEIF(C$2:C$57,C9,P$2:P$57),"N/A") | R9: Documento aderente aos critérios avaliados. | S9: Manter revisão periódica. | T9: Bruno Costa | U9: 46301 | V9: Concluído
A10: =IF(B10="","",ROW()-4) | B10: 46241 | C10: Recursos Humanos | D10: Controle de Acesso | E10: Checklist de Auditoria | F10: 3 | G10: SIM | H10: SIM | I10: 46086 | J10: SIM | K10: Conformidade | L10: =IF(G10="","",IF(G10="SIM",1,0)) | M10: =IF(H10="","",IF(H10="SIM",1,0)) | N10: =IF(J10="","",IF(J10="SIM",1,0)) | O10: =IF(K10="","",IF(K10="Conformidade",1,IF(K10="Não Conformidade",0,IF(K10="Não Conformidade Grave",-1,"")))) | P10: =IF(COUNTA(G10,H10,J10,K10)=0,"",ROUND(AVERAGE(L10:O10)*100,0)) | Q10: =IFERROR(AVERAGEIF(C$2:C$57,C10,P$2:P$57),"N/A") | R10: Documento aderente aos critérios avaliados. | S10: Manter revisão periódica. | T10: Carla Souza | U10: 46333 | V10: Concluído
A11: =IF(B11="","",ROW()-4) | B11: 46181 | C11: Financeiro | D11: Auditoria de Processos | E11: Plano de Continuidade | F11: 4 | G11: SIM | H11: SIM | I11: 45388 | J11: SIM | K11: Não Conformidade | L11: =IF(G11="","",IF(G11="SIM",1,0)) | M11: =IF(H11="","",IF(H11="SIM",1,0)) | N11: =IF(J11="","",IF(J11="SIM",1,0)) | O11: =IF(K11="","",IF(K11="Conformidade",1,IF(K11="Não Conformidade",0,IF(K11="Não Conformidade Grave",-1,"")))) | P11: =IF(COUNTA(G11,H11,J11,K11)=0,"",ROUND(AVERAGE(L11:O11)*100,0)) | Q11: =IFERROR(AVERAGEIF(C$2:C$57,C11,P$2:P$57),"N/A") | R11: Foi identificada oportunidade de adequação documental. | S11: Executar validação com a área responsável | T11: Diego Alves | U11: 46273 | V11: Não iniciado
A12: =IF(B12="","",ROW()-4) | B12: 46212 | C12: Atendimento | D12: Atendimento ao Cliente | E12: Norma de Controle de Acesso | F12: 5 | G12: SIM | H12: SIM | I12: 45784 | J12: NÃO | K12: Conformidade | L12: =IF(G12="","",IF(G12="SIM",1,0)) | M12: =IF(H12="","",IF(H12="SIM",1,0)) | N12: =IF(J12="","",IF(J12="SIM",1,0)) | O12: =IF(K12="","",IF(K12="Conformidade",1,IF(K12="Não Conformidade",0,IF(K12="Não Conformidade Grave",-1,"")))) | P12: =IF(COUNTA(G12,H12,J12,K12)=0,"",ROUND(AVERAGE(L12:O12)*100,0)) | Q12: =IFERROR(AVERAGEIF(C$2:C$57,C12,P$2:P$57),"N/A") | R12: Foi identificada oportunidade de adequação documental. | S12: Criar documento e obter aprovação | T12: Fernanda Rocha | U12: 46304 | V12: Em andamento
A13: =IF(B13="","",ROW()-4) | B13: 46244 | C13: Tecnologia | D13: Contas a Pagar | E13: Política de Segurança da Informação | F13: 1 | G13: SIM | H13: NÃO | I13: 46181 | J13: SIM | K13: Conformidade | L13: =IF(G13="","",IF(G13="SIM",1,0)) | M13: =IF(H13="","",IF(H13="SIM",1,0)) | N13: =IF(J13="","",IF(J13="SIM",1,0)) | O13: =IF(K13="","",IF(K13="Conformidade",1,IF(K13="Não Conformidade",0,IF(K13="Não Conformidade Grave",-1,"")))) | P13: =IF(COUNTA(G13,H13,J13,K13)=0,"",ROUND(AVERAGE(L13:O13)*100,0)) | Q13: =IFERROR(AVERAGEIF(C$2:C$57,C13,P$2:P$57),"N/A") | R13: Foi identificada oportunidade de adequação documental. | S13: Revisar conteúdo e publicar nova versão | T13: Gabriel Martins | U13: 46336 | V13: Aguardando validação
A14: =IF(B14="","",ROW()-4) | B14: 46184 | C14: PROCESSOS | D14: Treinamento Interno | E14: Fluxo de Aprovação de Compras | F14: 2 | G14: SIM | H14: SIM | I14: 45482 | J14: SIM | K14: Não Conformidade | L14: =IF(G14="","",IF(G14="SIM",1,0)) | M14: =IF(H14="","",IF(H14="SIM",1,0)) | N14: =IF(J14="","",IF(J14="SIM",1,0)) | O14: =IF(K14="","",IF(K14="Conformidade",1,IF(K14="Não Conformidade",0,IF(K14="Não Conformidade Grave",-1,"")))) | P14: =IF(COUNTA(G14,H14,J14,K14)=0,"",ROUND(AVERAGE(L14:O14)*100,0)) | Q14: =IFERROR(AVERAGEIF(C$2:C$57,C14,P$2:P$57),"N/A") | R14: Foi identificada oportunidade de adequação documental. | S14: Adequar ao padrão corporativo | T14: Ana Lima | U14: 46276 | V14: Não iniciado
A15: =IF(B15="","",ROW()-4) | B15: 46215 | C15: Qualidade | D15: Faturamento | E15: Checklist de Auditoria | F15: 3 | G15: NÃO | H15: SIM | I15: 45879 | J15: SIM | K15: Conformidade | L15: =IF(G15="","",IF(G15="SIM",1,0)) | M15: =IF(H15="","",IF(H15="SIM",1,0)) | N15: =IF(J15="","",IF(J15="SIM",1,0)) | O15: =IF(K15="","",IF(K15="Conformidade",1,IF(K15="Não Conformidade",0,IF(K15="Não Conformidade Grave",-1,"")))) | P15: =IF(COUNTA(G15,H15,J15,K15)=0,"",ROUND(AVERAGE(L15:O15)*100,0)) | Q15: =IFERROR(AVERAGEIF(C$2:C$57,C15,P$2:P$57),"N/A") | R15: Foi identificada oportunidade de adequação documental. | S15: Executar validação com a área responsável | T15: Bruno Costa | U15: 46307 | V15: Em andamento
A16: =IF(B16="","",ROW()-4) | B16: 46247 | C16: Recursos Humanos | D16: Compras | E16: Plano de Continuidade | F16: 4 | G16: SIM | H16: SIM | I16: 46276 | J16: NÃO | K16: Conformidade | L16: =IF(G16="","",IF(G16="SIM",1,0)) | M16: =IF(H16="","",IF(H16="SIM",1,0)) | N16: =IF(J16="","",IF(J16="SIM",1,0)) | O16: =IF(K16="","",IF(K16="Conformidade",1,IF(K16="Não Conformidade",0,IF(K16="Não Conformidade Grave",-1,"")))) | P16: =IF(COUNTA(G16,H16,J16,K16)=0,"",ROUND(AVERAGE(L16:O16)*100,0)) | Q16: =IFERROR(AVERAGEIF(C$2:C$57,C16,P$2:P$57),"N/A") | R16: Foi identificada oportunidade de adequação documental. | S16: Criar documento e obter aprovação | T16: Carla Souza | U16: 46339 | V16: Aguardando validação
A17: =IF(B17="","",ROW()-4) | B17: 46187 | C17: Financeiro | D17: Gestão de Incidentes | E17: Norma de Controle de Acesso | F17: 5 | G17: SIM | H17: SIM | I17: 45577 | J17: NÃO | K17: Não Conformidade | L17: =IF(G17="","",IF(G17="SIM",1,0)) | M17: =IF(H17="","",IF(H17="SIM",1,0)) | N17: =IF(J17="","",IF(J17="SIM",1,0)) | O17: =IF(K17="","",IF(K17="Conformidade",1,IF(K17="Não Conformidade",0,IF(K17="Não Conformidade Grave",-1,"")))) | P17: =IF(COUNTA(G17,H17,J17,K17)=0,"",ROUND(AVERAGE(L17:O17)*100,0)) | Q17: =IFERROR(AVERAGEIF(C$2:C$57,C17,P$2:P$57),"N/A") | R17: Foi identificada oportunidade de adequação documental. | S17: Revisar conteúdo e publicar nova versão | T17: Diego Alves | U17: 46279 | V17: Não iniciado
A18: =IF(B18="","",ROW()-4) | B18: 46218 | C18: Atendimento | D18: Admissão | E18: Política de Segurança da Informação | F18: 1 | G18: SIM | H18: NÃO | I18: 45974 | J18: SIM | K18: Não Conformidade Grave | L18: =IF(G18="","",IF(G18="SIM",1,0)) | M18: =IF(H18="","",IF(H18="SIM",1,0)) | N18: =IF(J18="","",IF(J18="SIM",1,0)) | O18: =IF(K18="","",IF(K18="Conformidade",1,IF(K18="Não Conformidade",0,IF(K18="Não Conformidade Grave",-1,"")))) | P18: =IF(COUNTA(G18,H18,J18,K18)=0,"",ROUND(AVERAGE(L18:O18)*100,0)) | Q18: =IFERROR(AVERAGEIF(C$2:C$57,C18,P$2:P$57),"N/A") | R18: Foi identificada oportunidade de adequação documental. | S18: Adequar ao padrão corporativo | T18: Fernanda Rocha | U18: 46310 | V18: Em andamento
A19: =IF(B19="","",ROW()-4) | B19: 46250 | C19: Tecnologia | D19: Gestão de Contratos | E19: Fluxo de Aprovação de Compras | F19: 2 | G19: SIM | H19: NÃO | I19: 46370 | J19: SIM | K19: Conformidade | L19: =IF(G19="","",IF(G19="SIM",1,0)) | M19: =IF(H19="","",IF(H19="SIM",1,0)) | N19: =IF(J19="","",IF(J19="SIM",1,0)) | O19: =IF(K19="","",IF(K19="Conformidade",1,IF(K19="Não Conformidade",0,IF(K19="Não Conformidade Grave",-1,"")))) | P19: =IF(COUNTA(G19,H19,J19,K19)=0,"",ROUND(AVERAGE(L19:O19)*100,0)) | Q19: =IFERROR(AVERAGEIF(C$2:C$57,C19,P$2:P$57),"N/A") | R19: Foi identificada oportunidade de adequação documental. | S19: Executar validação com a área responsável | T19: Gabriel Martins | U19: 46342 | V19: Aguardando validação
... A57: =IF(B57="","",ROW()-4) | B57: 46217 | C57: Qualidade | D57: Gestão de Incidentes | E57: Norma de Controle de Acesso | F57: 5 | G57: NÃO | H57: SIM | I57: 45692 | J57: SIM | K57: Conformidade | L57: =IF(G57="","",IF(G57="SIM",1,0)) | M57: =IF(H57="","",IF(H57="SIM",1,0)) | N57: =IF(J57="","",IF(J57="SIM",1,0)) | O57: =IF(K57="","",IF(K57="Conformidade",1,IF(K57="Não Conformidade",0,IF(K57="Não Conformidade Grave",-1,"")))) | P57: =IF(COUNTA(G57,H57,J57,K57)=0,"",ROUND(AVERAGE(L57:O57)*100,0)) | Q57: =IFERROR(AVERAGEIF(C$2:C$57,C57,P$2:P$57),"N/A") | R57: Foi identificada oportunidade de adequação documental. | S57: Revisar conteúdo e publicar nova versão | T57: Bruno Costa | U57: 46309 | V57: Em andamento
A58: 1 | B58: 18/09/2026 | C58: Mobilize | D58: Documentação | E58: Documento NC 01 | F58: 1 | G58: SIM | H58: NÃO | J58: NÃO
A59: 2 | B59: 18/09/2026 | C59: Mobilize | D59: Documentação | E59: Documento NC 02 | F59: 1 | G59: SIM | H59: NÃO | J59: NÃO
A60: 3 | B60: 18/09/2026 | C60: Mobilize | D60: Documentação | E60: Documento NC 03 | F60: 1 | G60: SIM | H60: NÃO | J60: NÃO
A61: 4 | B61: 18/09/2026 | C61: Mobilize | D61: Documentação | E61: Documento NC 04 | F61: 1 | G61: SIM | H61: NÃO | J61: NÃO
A62: 5 | B62: 18/09/2026 | C62: Mobilize | D62: Documentação | E62: Documento NC 05 | F62: 1 | G62: SIM | H62: NÃO | J62: NÃO
A63: 6 | B63: 18/09/2026 | C63: Mobilize | D63: Processos | E63: Documento NC 06 | F63: 1 | G63: SIM | H63: NÃO | J63: NÃO
A64: 7 | B64: 18/09/2026 | C64: Mobilize | D64: Indicadores | E64: Documento NC 07 | F64: 1 | G64: SIM | H64: NÃO | J64: NÃO
A65: 8 | B65: 18/09/2026 | C65: Mobilize | D65: Treinamento | E65: Documento NC 08 | F65: 1 | G65: SIM | H65: NÃO | J65: NÃO
A66: 9 | B66: 18/09/2026 | C66: Mobilize | D66: Clube FIQ | E66: Documento NC 09 | F66: 1 | G66: SIM | H66: NÃO | J66: NÃO
A67: 10 | B67: 18/09/2026 | C67: Mobilize | D67: Documentação | E67: D.C.231.EXTE | F67: 1 | G67: SIM | H67: NÃO | J67: NÃO
A68: 11 | B68: 18/09/2026 | C68: Mobilize | D68: Documentação | E68: D.C.232.EXTE | F68: 1 | G68: SIM | H68: NÃO | J68: NÃO
A69: 12 | B69: 18/09/2026 | C69: Mobilize | D69: Documentação | E69: D.C.1504.EXTE | F69: 1 | G69: SIM | H69: NÃO | J69: NÃO
... A72: 15 | B72: 18/09/2026 | C72: Mobilize | D72: Documentação | E72: D.C.136.EXTE | F72: 1 | G72: SIM | H72: NÃO | J72: NÃO

Sheet Indicadores
A1: ID Avaliação | B1: Data da avaliação | C1: Operação | D1: Processo avaliado | E1: Nome_Indicador | F1: Quantidade | G1: Existe indicador? | H1: Como é atualizado? | I1: No padrão? | J1: Conforme? | K1: Existência | L1: Atualização | M1: Padrão | N1: Conformidade | O1: Score Indicadores | P1: Geral | Q1: Observação | R1: Plano de Ação | S1: Responsável | T1: Prazo | U1: Status da Ação
A2: =IF(B2="","",ROW()-1) | B2: 46247 | C2: Qualidade | D2: Admissão | E2: Taxa de Absenteísmo | F2: 1 | G2: SIM | H2: Automático | I2: SIM | J2: Conformidade | K2: =IF(G2="","",IF(G2="SIM",1,0)) | L2: =IF(H2="","",IF(H2="Automático",1,IF(H2="Manual",0.5,IF(H2="Não atualizado",0,"")))) | M2: =IF(I2="","",IF(I2="SIM",1,0)) | N2: =IF(J2="","",IF(J2="Conformidade",1,IF(J2="Não Conformidade",0,IF(J2="Não Conformidade Grave",-1,"")))) | O2: =IF(COUNTA(G2:J2)=0,"",ROUND(AVERAGE(K2:N2)*100,0)) | P2: =IFERROR(AVERAGEIF(C$2:C$201,C2,O$2:O$201),"N/A") | Q2: Linha de exemplo - substitua pelos dados reais
A3: =IF(B3="","",ROW()-1) | B3: 46179 | C3: PROCESSOS | D3: Admissão | E3: Taxa de Absenteísmo | F3: 1 | G3: NÃO | H3: Não atualizado | I3: NÃO | J3: Não Conformidade Grave | K3: =IF(G3="","",IF(G3="SIM",1,0)) | L3: =IF(H3="","",IF(H3="Automático",1,IF(H3="Manual",0.5,IF(H3="Não atualizado",0,"")))) | M3: =IF(I3="","",IF(I3="SIM",1,0)) | N3: =IF(J3="","",IF(J3="Conformidade",1,IF(J3="Não Conformidade",0,IF(J3="Não Conformidade Grave",-1,"")))) | O3: =IF(COUNTA(G3:J3)=0,"",ROUND(AVERAGE(K3:N3)*100,0)) | P3: =IFERROR(AVERAGEIF(C$2:C$201,C3,O$2:O$201),"N/A") | Q3: Indicador requer melhoria de definição, atualização ou aderência. | R3: Formalizar indicador e definir responsável | S3: Ana Lima | T3: 46273 | U3: Não iniciado
A4: =IF(B4="","",ROW()-1) | B4: 46210 | C4: Qualidade | D4: Gestão de Contratos | E4: Índice de Retrabalho | F4: 2 | G4: SIM | H4: Automático | I4: SIM | J4: Conformidade | K4: =IF(G4="","",IF(G4="SIM",1,0)) | L4: =IF(H4="","",IF(H4="Automático",1,IF(H4="Manual",0.5,IF(H4="Não atualizado",0,"")))) | M4: =IF(I4="","",IF(I4="SIM",1,0)) | N4: =IF(J4="","",IF(J4="Conformidade",1,IF(J4="Não Conformidade",0,IF(J4="Não Conformidade Grave",-1,"")))) | O4: =IF(COUNTA(G4:J4)=0,"",ROUND(AVERAGE(K4:N4)*100,0)) | P4: =IFERROR(AVERAGEIF(C$2:C$201,C4,O$2:O$201),"N/A") | Q4: Indicador formalizado e acompanhado regularmente. | R4: Manter acompanhamento mensal. | S4: Bruno Costa | T4: 46304 | U4: Concluído
A5: =IF(B5="","",ROW()-1) | B5: 46242 | C5: Recursos Humanos | D5: Controle de Acesso | E5: Taxa de Conversão | F5: 3 | G5: SIM | H5: Automático | I5: SIM | J5: Conformidade | K5: =IF(G5="","",IF(G5="SIM",1,0)) | L5: =IF(H5="","",IF(H5="Automático",1,IF(H5="Manual",0.5,IF(H5="Não atualizado",0,"")))) | M5: =IF(I5="","",IF(I5="SIM",1,0)) | N5: =IF(J5="","",IF(J5="Conformidade",1,IF(J5="Não Conformidade",0,IF(J5="Não Conformidade Grave",-1,"")))) | O5: =IF(COUNTA(G5:J5)=0,"",ROUND(AVERAGE(K5:N5)*100,0)) | P5: =IFERROR(AVERAGEIF(C$2:C$201,C5,O$2:O$201),"N/A") | Q5: Indicador formalizado e acompanhado regularmente. | R5: Manter acompanhamento mensal. | S5: Carla Souza | T5: 46336 | U5: Concluído
A6: =IF(B6="","",ROW()-1) | B6: 46182 | C6: Financeiro | D6: Auditoria de Processos | E6: Índice de Satisfação | F6: 4 | G6: SIM | H6: Manual | I6: SIM | J6: Conformidade | K6: =IF(G6="","",IF(G6="SIM",1,0)) | L6: =IF(H6="","",IF(H6="Automático",1,IF(H6="Manual",0.5,IF(H6="Não atualizado",0,"")))) | M6: =IF(I6="","",IF(I6="SIM",1,0)) | N6: =IF(J6="","",IF(J6="Conformidade",1,IF(J6="Não Conformidade",0,IF(J6="Não Conformidade Grave",-1,"")))) | O6: =IF(COUNTA(G6:J6)=0,"",ROUND(AVERAGE(K6:N6)*100,0)) | P6: =IFERROR(AVERAGEIF(C$2:C$201,C6,O$2:O$201),"N/A") | Q6: Indicador formalizado e acompanhado regularmente. | R6: Manter acompanhamento mensal. | S6: Diego Alves | T6: 46276 | U6: Concluído
A7: =IF(B7="","",ROW()-1) | B7: 46213 | C7: Atendimento | D7: Atendimento ao Cliente | E7: Aderência ao Procedimento | F7: 5 | G7: SIM | H7: Automático | I7: NÃO | J7: Não Conformidade | K7: =IF(G7="","",IF(G7="SIM",1,0)) | L7: =IF(H7="","",IF(H7="Automático",1,IF(H7="Manual",0.5,IF(H7="Não atualizado",0,"")))) | M7: =IF(I7="","",IF(I7="SIM",1,0)) | N7: =IF(J7="","",IF(J7="Conformidade",1,IF(J7="Não Conformidade",0,IF(J7="Não Conformidade Grave",-1,"")))) | O7: =IF(COUNTA(G7:J7)=0,"",ROUND(AVERAGE(K7:N7)*100,0)) | P7: =IFERROR(AVERAGEIF(C$2:C$201,C7,O$2:O$201),"N/A") | Q7: Indicador requer melhoria de definição, atualização ou aderência. | R7: Formalizar indicador e definir responsável | S7: Fernanda Rocha | T7: 46307 | U7: Em andamento
A8: =IF(B8="","",ROW()-1) | B8: 46245 | C8: Tecnologia | D8: Contas a Pagar | E8: Taxa de Absenteísmo | F8: 6 | G8: SIM | H8: Não atualizado | I8: SIM | J8: Conformidade | K8: =IF(G8="","",IF(G8="SIM",1,0)) | L8: =IF(H8="","",IF(H8="Automático",1,IF(H8="Manual",0.5,IF(H8="Não atualizado",0,"")))) | M8: =IF(I8="","",IF(I8="SIM",1,0)) | N8: =IF(J8="","",IF(J8="Conformidade",1,IF(J8="Não Conformidade",0,IF(J8="Não Conformidade Grave",-1,"")))) | O8: =IF(COUNTA(G8:J8)=0,"",ROUND(AVERAGE(K8:N8)*100,0)) | P8: =IFERROR(AVERAGEIF(C$2:C$201,C8,O$2:O$201),"N/A") | Q8: Indicador requer melhoria de definição, atualização ou aderência. | R8: Automatizar rotina de atualização | S8: Gabriel Martins | T8: 46339 | U8: Aguardando validação
A9: =IF(B9="","",ROW()-1) | B9: 46185 | C9: PROCESSOS | D9: Treinamento Interno | E9: Índice de Retrabalho | F9: 7 | G9: SIM | H9: Manual | I9: SIM | J9: Conformidade | K9: =IF(G9="","",IF(G9="SIM",1,0)) | L9: =IF(H9="","",IF(H9="Automático",1,IF(H9="Manual",0.5,IF(H9="Não atualizado",0,"")))) | M9: =IF(I9="","",IF(I9="SIM",1,0)) | N9: =IF(J9="","",IF(J9="Conformidade",1,IF(J9="Não Conformidade",0,IF(J9="Não Conformidade Grave",-1,"")))) | O9: =IF(COUNTA(G9:J9)=0,"",ROUND(AVERAGE(K9:N9)*100,0)) | P9: =IFERROR(AVERAGEIF(C$2:C$201,C9,O$2:O$201),"N/A") | Q9: Indicador formalizado e acompanhado regularmente. | R9: Manter acompanhamento mensal. | S9: Ana Lima | T9: 46279 | U9: Concluído
A10: =IF(B10="","",ROW()-1) | B10: 46216 | C10: Qualidade | D10: Faturamento | E10: Taxa de Conversão | F10: 8 | G10: SIM | H10: Automático | I10: SIM | J10: Conformidade | K10: =IF(G10="","",IF(G10="SIM",1,0)) | L10: =IF(H10="","",IF(H10="Automático",1,IF(H10="Manual",0.5,IF(H10="Não atualizado",0,"")))) | M10: =IF(I10="","",IF(I10="SIM",1,0)) | N10: =IF(J10="","",IF(J10="Conformidade",1,IF(J10="Não Conformidade",0,IF(J10="Não Conformidade Grave",-1,"")))) | O10: =IF(COUNTA(G10:J10)=0,"",ROUND(AVERAGE(K10:N10)*100,0)) | P10: =IFERROR(AVERAGEIF(C$2:C$201,C10,O$2:O$201),"N/A") | Q10: Indicador formalizado e acompanhado regularmente. | R10: Manter acompanhamento mensal. | S10: Bruno Costa | T10: 46310 | U10: Concluído
A11: =IF(B11="","",ROW()-1) | B11: 46248 | C11: Recursos Humanos | D11: Compras | E11: Índice de Satisfação | F11: 1 | G11: SIM | H11: Automático | I11: NÃO | J11: Não Conformidade | K11: =IF(G11="","",IF(G11="SIM",1,0)) | L11: =IF(H11="","",IF(H11="Automático",1,IF(H11="Manual",0.5,IF(H11="Não atualizado",0,"")))) | M11: =IF(I11="","",IF(I11="SIM",1,0)) | N11: =IF(J11="","",IF(J11="Conformidade",1,IF(J11="Não Conformidade",0,IF(J11="Não Conformidade Grave",-1,"")))) | O11: =IF(COUNTA(G11:J11)=0,"",ROUND(AVERAGE(K11:N11)*100,0)) | P11: =IFERROR(AVERAGEIF(C$2:C$201,C11,O$2:O$201),"N/A") | Q11: Indicador requer melhoria de definição, atualização ou aderência. | R11: Formalizar indicador e definir responsável | S11: Carla Souza | T11: 46342 | U11: Aguardando validação
A12: =IF(B12="","",ROW()-1) | B12: 46188 | C12: Financeiro | D12: Gestão de Incidentes | E12: Aderência ao Procedimento | F12: 2 | G12: NÃO | H12: Não atualizado | I12: SIM | J12: Conformidade | K12: =IF(G12="","",IF(G12="SIM",1,0)) | L12: =IF(H12="","",IF(H12="Automático",1,IF(H12="Manual",0.5,IF(H12="Não atualizado",0,"")))) | M12: =IF(I12="","",IF(I12="SIM",1,0)) | N12: =IF(J12="","",IF(J12="Conformidade",1,IF(J12="Não Conformidade",0,IF(J12="Não Conformidade Grave",-1,"")))) | O12: =IF(COUNTA(G12:J12)=0,"",ROUND(AVERAGE(K12:N12)*100,0)) | P12: =IFERROR(AVERAGEIF(C$2:C$201,C12,O$2:O$201),"N/A") | Q12: Indicador requer melhoria de definição, atualização ou aderência. | R12: Automatizar rotina de atualização | S12: Diego Alves | T12: 46282 | U12: Não iniciado
A13: =IF(B13="","",ROW()-1) | B13: 46219 | C13: Atendimento | D13: Admissão | E13: Taxa de Absenteísmo | F13: 3 | G13: SIM | H13: Não atualizado | I13: SIM | J13: Conformidade | K13: =IF(G13="","",IF(G13="SIM",1,0)) | L13: =IF(H13="","",IF(H13="Automático",1,IF(H13="Manual",0.5,IF(H13="Não atualizado",0,"")))) | M13: =IF(I13="","",IF(I13="SIM",1,0)) | N13: =IF(J13="","",IF(J13="Conformidade",1,IF(J13="Não Conformidade",0,IF(J13="Não Conformidade Grave",-1,"")))) | O13: =IF(COUNTA(G13:J13)=0,"",ROUND(AVERAGE(K13:N13)*100,0)) | P13: =IFERROR(AVERAGEIF(C$2:C$201,C13,O$2:O$201),"N/A") | Q13: Indicador requer melhoria de definição, atualização ou aderência. | R13: Documentar meta, fórmula e periodicidade | S13: Fernanda Rocha | T13: 46313 | U13: Em andamento
A14: =IF(B14="","",ROW()-1) | B14: 46251 | C14: Tecnologia | D14: Gestão de Contratos | E14: Índice de Retrabalho | F14: 4 | G14: SIM | H14: Automático | I14: NÃO | J14: Conformidade | K14: =IF(G14="","",IF(G14="SIM",1,0)) | L14: =IF(H14="","",IF(H14="Automático",1,IF(H14="Manual",0.5,IF(H14="Não atualizado",0,"")))) | M14: =IF(I14="","",IF(I14="SIM",1,0)) | N14: =IF(J14="","",IF(J14="Conformidade",1,IF(J14="Não Conformidade",0,IF(J14="Não Conformidade Grave",-1,"")))) | O14: =IF(COUNTA(G14:J14)=0,"",ROUND(AVERAGE(K14:N14)*100,0)) | P14: =IFERROR(AVERAGEIF(C$2:C$201,C14,O$2:O$201),"N/A") | Q14: Indicador requer melhoria de definição, atualização ou aderência. | R14: Revisar causa da não conformidade | S14: Gabriel Martins | T14: 46345 | U14: Aguardando validação
... A52: =IF(B52="","",ROW()-1) | B52: 46218 | C52: Qualidade | D52: Gestão de Incidentes | E52: Aderência ao Procedimento | F52: 2 | G52: SIM | H52: Automático | I52: SIM | J52: Conformidade | K52: =IF(G52="","",IF(G52="SIM",1,0)) | L52: =IF(H52="","",IF(H52="Automático",1,IF(H52="Manual",0.5,IF(H52="Não atualizado",0,"")))) | M52: =IF(I52="","",IF(I52="SIM",1,0)) | N52: =IF(J52="","",IF(J52="Conformidade",1,IF(J52="Não Conformidade",0,IF(J52="Não Conformidade Grave",-1,"")))) | O52: =IF(COUNTA(G52:J52)=0,"",ROUND(AVERAGE(K52:N52)*100,0)) | P52: =IFERROR(AVERAGEIF(C$2:C$201,C52,O$2:O$201),"N/A") | Q52: Indicador formalizado e acompanhado regularmente. | R52: Manter acompanhamento mensal. | S52: Bruno Costa | T52: 46316 | U52: Concluído
A53: =IF(B53="","",ROW()-1) | K53: =IF(G53="","",IF(G53="SIM",1,0)) | L53: =IF(H53="","",IF(H53="Automático",1,IF(H53="Manual",0.5,IF(H53="Não atualizado",0,"")))) | M53: =IF(I53="","",IF(I53="SIM",1,0)) | N53: =IF(J53="","",IF(J53="Conformidade",1,IF(J53="Não Conformidade",0,IF(J53="Não Conformidade Grave",-1,"")))) | O53: =IF(COUNTA(G53:J53)=0,"",ROUND(AVERAGE(K53:N53)*100,0)) | P53: =IFERROR(AVERAGEIF(C$2:C$201,C53,O$2:O$201),"N/A")
A54: =IF(B54="","",ROW()-1) | K54: =IF(G54="","",IF(G54="SIM",1,0)) | L54: =IF(H54="","",IF(H54="Automático",1,IF(H54="Manual",0.5,IF(H54="Não atualizado",0,"")))) | M54: =IF(I54="","",IF(I54="SIM",1,0)) | N54: =IF(J54="","",IF(J54="Conformidade",1,IF(J54="Não Conformidade",0,IF(J54="Não Conformidade Grave",-1,"")))) | O54: =IF(COUNTA(G54:J54)=0,"",ROUND(AVERAGE(K54:N54)*100,0)) | P54: =IFERROR(AVERAGEIF(C$2:C$201,C54,O$2:O$201),"N/A")
A55: =IF(B55="","",ROW()-1) | K55: =IF(G55="","",IF(G55="SIM",1,0)) | L55: =IF(H55="","",IF(H55="Automático",1,IF(H55="Manual",0.5,IF(H55="Não atualizado",0,"")))) | M55: =IF(I55="","",IF(I55="SIM",1,0)) | N55: =IF(J55="","",IF(J55="Conformidade",1,IF(J55="Não Conformidade",0,IF(J55="Não Conformidade Grave",-1,"")))) | O55: =IF(COUNTA(G55:J55)=0,"",ROUND(AVERAGE(K55:N55)*100,0)) | P55: =IFERROR(AVERAGEIF(C$2:C$201,C55,O$2:O$201),"N/A")
A56: =IF(B56="","",ROW()-1) | K56: =IF(G56="","",IF(G56="SIM",1,0)) | L56: =IF(H56="","",IF(H56="Automático",1,IF(H56="Manual",0.5,IF(H56="Não atualizado",0,"")))) | M56: =IF(I56="","",IF(I56="SIM",1,0)) | N56: =IF(J56="","",IF(J56="Conformidade",1,IF(J56="Não Conformidade",0,IF(J56="Não Conformidade Grave",-1,"")))) | O56: =IF(COUNTA(G56:J56)=0,"",ROUND(AVERAGE(K56:N56)*100,0)) | P56: =IFERROR(AVERAGEIF(C$2:C$201,C56,O$2:O$201),"N/A")
A57: =IF(B57="","",ROW()-1) | K57: =IF(G57="","",IF(G57="SIM",1,0)) | L57: =IF(H57="","",IF(H57="Automático",1,IF(H57="Manual",0.5,IF(H57="Não atualizado",0,"")))) | M57: =IF(I57="","",IF(I57="SIM",1,0)) | N57: =IF(J57="","",IF(J57="Conformidade",1,IF(J57="Não Conformidade",0,IF(J57="Não Conformidade Grave",-1,"")))) | O57: =IF(COUNTA(G57:J57)=0,"",ROUND(AVERAGE(K57:N57)*100,0)) | P57: =IFERROR(AVERAGEIF(C$2:C$201,C57,O$2:O$201),"N/A")
A58: =IF(B58="","",ROW()-1) | K58: =IF(G58="","",IF(G58="SIM",1,0)) | L58: =IF(H58="","",IF(H58="Automático",1,IF(H58="Manual",0.5,IF(H58="Não atualizado",0,"")))) | M58: =IF(I58="","",IF(I58="SIM",1,0)) | N58: =IF(J58="","",IF(J58="Conformidade",1,IF(J58="Não Conformidade",0,IF(J58="Não Conformidade Grave",-1,"")))) | O58: =IF(COUNTA(G58:J58)=0,"",ROUND(AVERAGE(K58:N58)*100,0)) | P58: =IFERROR(AVERAGEIF(C$2:C$201,C58,O$2:O$201),"N/A")
A59: =IF(B59="","",ROW()-1) | K59: =IF(G59="","",IF(G59="SIM",1,0)) | L59: =IF(H59="","",IF(H59="Automático",1,IF(H59="Manual",0.5,IF(H59="Não atualizado",0,"")))) | M59: =IF(I59="","",IF(I59="SIM",1,0)) | N59: =IF(J59="","",IF(J59="Conformidade",1,IF(J59="Não Conformidade",0,IF(J59="Não Conformidade Grave",-1,"")))) | O59: =IF(COUNTA(G59:J59)=0,"",ROUND(AVERAGE(K59:N59)*100,0)) | P59: =IFERROR(AVERAGEIF(C$2:C$201,C59,O$2:O$201),"N/A")
A60: =IF(B60="","",ROW()-1) | K60: =IF(G60="","",IF(G60="SIM",1,0)) | L60: =IF(H60="","",IF(H60="Automático",1,IF(H60="Manual",0.5,IF(H60="Não atualizado",0,"")))) | M60: =IF(I60="","",IF(I60="SIM",1,0)) | N60: =IF(J60="","",IF(J60="Conformidade",1,IF(J60="Não Conformidade",0,IF(J60="Não Conformidade Grave",-1,"")))) | O60: =IF(COUNTA(G60:J60)=0,"",ROUND(AVERAGE(K60:N60)*100,0)) | P60: =IFERROR(AVERAGEIF(C$2:C$201,C60,O$2:O$201),"N/A")
A61: =IF(B61="","",ROW()-1) | K61: =IF(G61="","",IF(G61="SIM",1,0)) | L61: =IF(H61="","",IF(H61="Automático",1,IF(H61="Manual",0.5,IF(H61="Não atualizado",0,"")))) | M61: =IF(I61="","",IF(I61="SIM",1,0)) | N61: =IF(J61="","",IF(J61="Conformidade",1,IF(J61="Não Conformidade",0,IF(J61="Não Conformidade Grave",-1,"")))) | O61: =IF(COUNTA(G61:J61)=0,"",ROUND(AVERAGE(K61:N61)*100,0)) | P61: =IFERROR(AVERAGEIF(C$2:C$201,C61,O$2:O$201),"N/A")
A62: =IF(B62="","",ROW()-1) | K62: =IF(G62="","",IF(G62="SIM",1,0)) | L62: =IF(H62="","",IF(H62="Automático",1,IF(H62="Manual",0.5,IF(H62="Não atualizado",0,"")))) | M62: =IF(I62="","",IF(I62="SIM",1,0)) | N62: =IF(J62="","",IF(J62="Conformidade",1,IF(J62="Não Conformidade",0,IF(J62="Não Conformidade Grave",-1,"")))) | O62: =IF(COUNTA(G62:J62)=0,"",ROUND(AVERAGE(K62:N62)*100,0)) | P62: =IFERROR(AVERAGEIF(C$2:C$201,C62,O$2:O$201),"N/A")
A63: =IF(B63="","",ROW()-1) | K63: =IF(G63="","",IF(G63="SIM",1,0)) | L63: =IF(H63="","",IF(H63="Automático",1,IF(H63="Manual",0.5,IF(H63="Não atualizado",0,"")))) | M63: =IF(I63="","",IF(I63="SIM",1,0)) | N63: =IF(J63="","",IF(J63="Conformidade",1,IF(J63="Não Conformidade",0,IF(J63="Não Conformidade Grave",-1,"")))) | O63: =IF(COUNTA(G63:J63)=0,"",ROUND(AVERAGE(K63:N63)*100,0)) | P63: =IFERROR(AVERAGEIF(C$2:C$201,C63,O$2:O$201),"N/A")
A64: =IF(B64="","",ROW()-1) | K64: =IF(G64="","",IF(G64="SIM",1,0)) | L64: =IF(H64="","",IF(H64="Automático",1,IF(H64="Manual",0.5,IF(H64="Não atualizado",0,"")))) | M64: =IF(I64="","",IF(I64="SIM",1,0)) | N64: =IF(J64="","",IF(J64="Conformidade",1,IF(J64="Não Conformidade",0,IF(J64="Não Conformidade Grave",-1,"")))) | O64: =IF(COUNTA(G64:J64)=0,"",ROUND(AVERAGE(K64:N64)*100,0)) | P64: =IFERROR(AVERAGEIF(C$2:C$201,C64,O$2:O$201),"N/A")
... A201: =IF(B201="","",ROW()-1) | K201: =IF(G201="","",IF(G201="SIM",1,0)) | L201: =IF(H201="","",IF(H201="Automático",1,IF(H201="Manual",0.5,IF(H201="Não atualizado",0,"")))) | M201: =IF(I201="","",IF(I201="SIM",1,0)) | N201: =IF(J201="","",IF(J201="Conformidade",1,IF(J201="Não Conformidade",0,IF(J201="Não Conformidade Grave",-1,"")))) | O201: =IF(COUNTA(G201:J201)=0,"",ROUND(AVERAGE(K201:N201)*100,0)) | P201: =IFERROR(AVERAGEIF(C$2:C$201,C201,O$2:O$201),"N/A")
A202: 1 | B202: 18/09/2026 | C202: Mobilize | D202: Indicadores | E202: NS | F202: 1 | G202: SIM | H202: Manual | I202: NÃO | J202: Não Conformidade
A203: 2 | B203: 18/09/2026 | C203: Mobilize | D203: Indicadores | E203: PCA | F203: 1 | G203: SIM | H203: Manual | I203: NÃO | J203: Não Conformidade
A204: 3 | B204: 18/09/2026 | C204: Mobilize | D204: Indicadores | E204: TMA | F204: 1 | G204: SIM | H204: Manual | I204: NÃO | J204: Não Conformidade
A205: 4 | B205: 18/09/2026 | C205: Mobilize | D205: Indicadores | E205: TME | F205: 1 | G205: SIM | H205: Manual | I205: NÃO | J205: Não Conformidade
A206: 5 | B206: 18/09/2026 | C206: Mobilize | D206: Indicadores | E206: CSAT | F206: 1 | G206: SIM | H206: Manual | I206: NÃO | J206: Não Conformidade
A207: 6 | B207: 18/09/2026 | C207: Mobilize | D207: Indicadores | E207: FCR | F207: 1 | G207: SIM | H207: Manual | I207: NÃO | J207: Não Conformidade
A208: 7 | B208: 18/09/2026 | C208: Mobilize | D208: Indicadores | E208: SLA | F208: 1 | G208: SIM | H208: Manual | I208: NÃO | J208: Não Conformidade
A209: 8 | B209: 18/09/2026 | C209: Mobilize | D209: Indicadores | E209: HC | F209: 1 | G209: SIM | H209: Manual | I209: NÃO | J209: Não Conformidade
A210: 9 | B210: 18/09/2026 | C210: Mobilize | D210: Indicadores | E210: ABS | F210: 1 | G210: SIM | H210: Manual | I210: NÃO | J210: Não Conformidade
A211: 10 | B211: 18/09/2026 | C211: Mobilize | D211: Indicadores | E211: TO | F211: 1 | G211: SIM | H211: Manual | I211: NÃO | J211: Não Conformidade

Sheet Treinamento
A1: ID Avaliação | B1: Data da avaliação | C1: Operação | D1: Processo avaliado | E1: Nome_Treinamento | F1: Quantidade | G1: Treinamento está coerente aos documentos? | H1: Treinamento foi aplicado? | I1: Houve atualização? | J1: Conforme? | K1: Coerência | L1: Aplicação | M1: Atualização | N1: Conformidade | O1: Score Treinamento | P1: Geral | Q1: Observação | R1: Plano de Ação | S1: Responsável | T1: Prazo | U1: Status da Ação
A2: =IF(B2="","",ROW()-1) | B2: 46247 | C2: Exemplo (apagar) | D2: Admissão | E2: Treinamento - Admissão | F2: 1 | G2: SIM | H2: SIM | I2: NÃO | J2: Não Conformidade | K2: =IF(G2="","",IF(G2="SIM",1,0)) | L2: =IF(H2="","",IF(H2="SIM",1,0)) | M2: =IF(I2="","",IF(I2="SIM",1,0)) | N2: =IF(J2="","",IF(J2="Conformidade",1,IF(J2="Não Conformidade",0,IF(J2="Não Conformidade Grave",-1,"")))) | O2: =IF(COUNTA(G2:J2)=0,"",ROUND(AVERAGE(K2:N2)*100,0)) | P2: =IFERROR(AVERAGEIF(C$2:C$201,C2,O$2:O$201),"N/A") | Q2: Linha de exemplo - substitua pelos dados reais
A3: =IF(B3="","",ROW()-1) | B3: 46180 | C3: Qualidade | D3: Faturamento | E3: Integração de Novos Colaboradores | F3: 5 | G3: NÃO | H3: NÃO | I3: NÃO | J3: Não Conformidade Grave | K3: =IF(G3="","",IF(G3="SIM",1,0)) | L3: =IF(H3="","",IF(H3="SIM",1,0)) | M3: =IF(I3="","",IF(I3="SIM",1,0)) | N3: =IF(J3="","",IF(J3="Conformidade",1,IF(J3="Não Conformidade",0,IF(J3="Não Conformidade Grave",-1,"")))) | O3: =IF(COUNTA(G3:J3)=0,"",ROUND(AVERAGE(K3:N3)*100,0)) | P3: =IFERROR(AVERAGEIF(C$2:C$201,C3,O$2:O$201),"N/A") | Q3: Treinamento apresenta lacuna de conteúdo, aplicação ou atualização. | R3: Atualizar conteúdo conforme documentos vigentes | S3: Carla Souza | T3: 46275 | U3: Não iniciado
A4: =IF(B4="","",ROW()-1) | B4: 46211 | C4: Recursos Humanos | D4: Gestão de Contratos | E4: Gestão de Incidentes | F4: 6 | G4: SIM | H4: SIM | I4: SIM | J4: Conformidade | K4: =IF(G4="","",IF(G4="SIM",1,0)) | L4: =IF(H4="","",IF(H4="SIM",1,0)) | M4: =IF(I4="","",IF(I4="SIM",1,0)) | N4: =IF(J4="","",IF(J4="Conformidade",1,IF(J4="Não Conformidade",0,IF(J4="Não Conformidade Grave",-1,"")))) | O4: =IF(COUNTA(G4:J4)=0,"",ROUND(AVERAGE(K4:N4)*100,0)) | P4: =IFERROR(AVERAGEIF(C$2:C$201,C4,O$2:O$201),"N/A") | Q4: Treinamento aderente e com evidência de aplicação. | R4: Manter reciclagem periódica. | S4: Diego Alves | T4: 46306 | U4: Concluído
A5: =IF(B5="","",ROW()-1) | B5: 46243 | C5: Financeiro | D5: Contas a Pagar | E5: Proteção de Dados | F5: 7 | G5: SIM | H5: SIM | I5: SIM | J5: Conformidade | K5: =IF(G5="","",IF(G5="SIM",1,0)) | L5: =IF(H5="","",IF(H5="SIM",1,0)) | M5: =IF(I5="","",IF(I5="SIM",1,0)) | N5: =IF(J5="","",IF(J5="Conformidade",1,IF(J5="Não Conformidade",0,IF(J5="Não Conformidade Grave",-1,"")))) | O5: =IF(COUNTA(G5:J5)=0,"",ROUND(AVERAGE(K5:N5)*100,0)) | P5: =IFERROR(AVERAGEIF(C$2:C$201,C5,O$2:O$201),"N/A") | Q5: Treinamento aderente e com evidência de aplicação. | R5: Manter reciclagem periódica. | S5: Fernanda Rocha | T5: 46338 | U5: Concluído
A6: =IF(B6="","",ROW()-1) | B6: 46183 | C6: Atendimento | D6: Gestão de Incidentes | E6: Qualidade Operacional | F6: 8 | G6: SIM | H6: SIM | I6: SIM | J6: Conformidade | K6: =IF(G6="","",IF(G6="SIM",1,0)) | L6: =IF(H6="","",IF(H6="SIM",1,0)) | M6: =IF(I6="","",IF(I6="SIM",1,0)) | N6: =IF(J6="","",IF(J6="Conformidade",1,IF(J6="Não Conformidade",0,IF(J6="Não Conformidade Grave",-1,"")))) | O6: =IF(COUNTA(G6:J6)=0,"",ROUND(AVERAGE(K6:N6)*100,0)) | P6: =IFERROR(AVERAGEIF(C$2:C$201,C6,O$2:O$201),"N/A") | Q6: Treinamento aderente e com evidência de aplicação. | R6: Manter reciclagem periódica. | S6: Gabriel Martins | T6: 46278 | U6: Concluído
A7: =IF(B7="","",ROW()-1) | B7: 46214 | C7: Tecnologia | D7: Auditoria de Processos | E7: Atendimento ao Cliente | F7: 9 | G7: SIM | H7: SIM | I7: NÃO | J7: Conformidade | K7: =IF(G7="","",IF(G7="SIM",1,0)) | L7: =IF(H7="","",IF(H7="SIM",1,0)) | M7: =IF(I7="","",IF(I7="SIM",1,0)) | N7: =IF(J7="","",IF(J7="Conformidade",1,IF(J7="Não Conformidade",0,IF(J7="Não Conformidade Grave",-1,"")))) | O7: =IF(COUNTA(G7:J7)=0,"",ROUND(AVERAGE(K7:N7)*100,0)) | P7: =IFERROR(AVERAGEIF(C$2:C$201,C7,O$2:O$201),"N/A") | Q7: Treinamento apresenta lacuna de conteúdo, aplicação ou atualização. | R7: Atualizar conteúdo conforme documentos vigentes | S7: Ana Lima | T7: 46309 | U7: Em andamento
A8: =IF(B8="","",ROW()-1) | B8: 46246 | C8: PROCESSOS | D8: Faturamento | E8: Controles Financeiros | F8: 10 | G8: SIM | H8: SIM | I8: SIM | J8: Não Conformidade | K8: =IF(G8="","",IF(G8="SIM",1,0)) | L8: =IF(H8="","",IF(H8="SIM",1,0)) | M8: =IF(I8="","",IF(I8="SIM",1,0)) | N8: =IF(J8="","",IF(J8="Conformidade",1,IF(J8="Não Conformidade",0,IF(J8="Não Conformidade Grave",-1,"")))) | O8: =IF(COUNTA(G8:J8)=0,"",ROUND(AVERAGE(K8:N8)*100,0)) | P8: =IFERROR(AVERAGEIF(C$2:C$201,C8,O$2:O$201),"N/A") | Q8: Treinamento apresenta lacuna de conteúdo, aplicação ou atualização. | R8: Programar nova turma e registrar presença | S8: Bruno Costa | T8: 46341 | U8: Aguardando validação
A9: =IF(B9="","",ROW()-1) | B9: 46186 | C9: Qualidade | D9: Gestão de Contratos | E9: Gestão de Contratos | F9: 11 | G9: SIM | H9: NÃO | I9: SIM | J9: Conformidade | K9: =IF(G9="","",IF(G9="SIM",1,0)) | L9: =IF(H9="","",IF(H9="SIM",1,0)) | M9: =IF(I9="","",IF(I9="SIM",1,0)) | N9: =IF(J9="","",IF(J9="Conformidade",1,IF(J9="Não Conformidade",0,IF(J9="Não Conformidade Grave",-1,"")))) | O9: =IF(COUNTA(G9:J9)=0,"",ROUND(AVERAGE(K9:N9)*100,0)) | P9: =IFERROR(AVERAGEIF(C$2:C$201,C9,O$2:O$201),"N/A") | Q9: Treinamento apresenta lacuna de conteúdo, aplicação ou atualização. | R9: Revisar material e obter aprovação | S9: Carla Souza | T9: 46281 | U9: Não iniciado
A10: =IF(B10="","",ROW()-1) | B10: 46217 | C10: Recursos Humanos | D10: Contas a Pagar | E10: Segurança da Informação | F10: 12 | G10: SIM | H10: SIM | I10: SIM | J10: Conformidade | K10: =IF(G10="","",IF(G10="SIM",1,0)) | L10: =IF(H10="","",IF(H10="SIM",1,0)) | M10: =IF(I10="","",IF(I10="SIM",1,0)) | N10: =IF(J10="","",IF(J10="Conformidade",1,IF(J10="Não Conformidade",0,IF(J10="Não Conformidade Grave",-1,"")))) | O10: =IF(COUNTA(G10:J10)=0,"",ROUND(AVERAGE(K10:N10)*100,0)) | P10: =IFERROR(AVERAGEIF(C$2:C$201,C10,O$2:O$201),"N/A") | Q10: Treinamento aderente e com evidência de aplicação. | R10: Manter reciclagem periódica. | S10: Diego Alves | T10: 46312 | U10: Concluído
A11: =IF(B11="","",ROW()-1) | B11: 46249 | C11: Financeiro | D11: Gestão de Incidentes | E11: Política de Compras | F11: 13 | G11: NÃO | H11: SIM | I11: NÃO | J11: Conformidade | K11: =IF(G11="","",IF(G11="SIM",1,0)) | L11: =IF(H11="","",IF(H11="SIM",1,0)) | M11: =IF(I11="","",IF(I11="SIM",1,0)) | N11: =IF(J11="","",IF(J11="Conformidade",1,IF(J11="Não Conformidade",0,IF(J11="Não Conformidade Grave",-1,"")))) | O11: =IF(COUNTA(G11:J11)=0,"",ROUND(AVERAGE(K11:N11)*100,0)) | P11: =IFERROR(AVERAGEIF(C$2:C$201,C11,O$2:O$201),"N/A") | Q11: Treinamento apresenta lacuna de conteúdo, aplicação ou atualização. | R11: Atualizar conteúdo conforme documentos vigentes | S11: Fernanda Rocha | T11: 46344 | U11: Aguardando validação
A12: =IF(B12="","",ROW()-1) | B12: 46189 | C12: Atendimento | D12: Auditoria de Processos | E12: Auditoria Interna | F12: 14 | G12: SIM | H12: SIM | I12: SIM | J12: Conformidade | K12: =IF(G12="","",IF(G12="SIM",1,0)) | L12: =IF(H12="","",IF(H12="SIM",1,0)) | M12: =IF(I12="","",IF(I12="SIM",1,0)) | N12: =IF(J12="","",IF(J12="Conformidade",1,IF(J12="Não Conformidade",0,IF(J12="Não Conformidade Grave",-1,"")))) | O12: =IF(COUNTA(G12:J12)=0,"",ROUND(AVERAGE(K12:N12)*100,0)) | P12: =IFERROR(AVERAGEIF(C$2:C$201,C12,O$2:O$201),"N/A") | Q12: Treinamento aderente e com evidência de aplicação. | R12: Manter reciclagem periódica. | S12: Gabriel Martins | T12: 46284 | U12: Concluído
A13: =IF(B13="","",ROW()-1) | B13: 46220 | C13: Tecnologia | D13: Faturamento | E13: Integração de Novos Colaboradores | F13: 15 | G13: SIM | H13: SIM | I13: SIM | J13: Não Conformidade | K13: =IF(G13="","",IF(G13="SIM",1,0)) | L13: =IF(H13="","",IF(H13="SIM",1,0)) | M13: =IF(I13="","",IF(I13="SIM",1,0)) | N13: =IF(J13="","",IF(J13="Conformidade",1,IF(J13="Não Conformidade",0,IF(J13="Não Conformidade Grave",-1,"")))) | O13: =IF(COUNTA(G13:J13)=0,"",ROUND(AVERAGE(K13:N13)*100,0)) | P13: =IFERROR(AVERAGEIF(C$2:C$201,C13,O$2:O$201),"N/A") | Q13: Treinamento apresenta lacuna de conteúdo, aplicação ou atualização. | R13: Revisar material e obter aprovação | S13: Ana Lima | T13: 46315 | U13: Em andamento
A14: =IF(B14="","",ROW()-1) | B14: 46252 | C14: PROCESSOS | D14: Gestão de Contratos | E14: Gestão de Incidentes | F14: 16 | G14: SIM | H14: SIM | I14: NÃO | J14: Conformidade | K14: =IF(G14="","",IF(G14="SIM",1,0)) | L14: =IF(H14="","",IF(H14="SIM",1,0)) | M14: =IF(I14="","",IF(I14="SIM",1,0)) | N14: =IF(J14="","",IF(J14="Conformidade",1,IF(J14="Não Conformidade",0,IF(J14="Não Conformidade Grave",-1,"")))) | O14: =IF(COUNTA(G14:J14)=0,"",ROUND(AVERAGE(K14:N14)*100,0)) | P14: =IFERROR(AVERAGEIF(C$2:C$201,C14,O$2:O$201),"N/A") | Q14: Treinamento apresenta lacuna de conteúdo, aplicação ou atualização. | R14: Tratar não conformidade e avaliar eficácia | S14: Bruno Costa | T14: 46347 | U14: Aguardando validação
... A52: =IF(B52="","",ROW()-1) | B52: 46221 | C52: Recursos Humanos | D52: Auditoria de Processos | E52: Auditoria Interna | F52: 28 | G52: SIM | H52: SIM | I52: SIM | J52: Conformidade | K52: =IF(G52="","",IF(G52="SIM",1,0)) | L52: =IF(H52="","",IF(H52="SIM",1,0)) | M52: =IF(I52="","",IF(I52="SIM",1,0)) | N52: =IF(J52="","",IF(J52="Conformidade",1,IF(J52="Não Conformidade",0,IF(J52="Não Conformidade Grave",-1,"")))) | O52: =IF(COUNTA(G52:J52)=0,"",ROUND(AVERAGE(K52:N52)*100,0)) | P52: =IFERROR(AVERAGEIF(C$2:C$201,C52,O$2:O$201),"N/A") | Q52: Treinamento aderente e com evidência de aplicação. | R52: Manter reciclagem periódica. | S52: Diego Alves | T52: 46320 | U52: Concluído
A53: =IF(B53="","",ROW()-1) | K53: =IF(G53="","",IF(G53="SIM",1,0)) | L53: =IF(H53="","",IF(H53="SIM",1,0)) | M53: =IF(I53="","",IF(I53="SIM",1,0)) | N53: =IF(J53="","",IF(J53="Conformidade",1,IF(J53="Não Conformidade",0,IF(J53="Não Conformidade Grave",-1,"")))) | O53: =IF(COUNTA(G53:J53)=0,"",ROUND(AVERAGE(K53:N53)*100,0)) | P53: =IFERROR(AVERAGEIF(C$2:C$201,C53,O$2:O$201),"N/A")
A54: =IF(B54="","",ROW()-1) | K54: =IF(G54="","",IF(G54="SIM",1,0)) | L54: =IF(H54="","",IF(H54="SIM",1,0)) | M54: =IF(I54="","",IF(I54="SIM",1,0)) | N54: =IF(J54="","",IF(J54="Conformidade",1,IF(J54="Não Conformidade",0,IF(J54="Não Conformidade Grave",-1,"")))) | O54: =IF(COUNTA(G54:J54)=0,"",ROUND(AVERAGE(K54:N54)*100,0)) | P54: =IFERROR(AVERAGEIF(C$2:C$201,C54,O$2:O$201),"N/A")
A55: =IF(B55="","",ROW()-1) | K55: =IF(G55="","",IF(G55="SIM",1,0)) | L55: =IF(H55="","",IF(H55="SIM",1,0)) | M55: =IF(I55="","",IF(I55="SIM",1,0)) | N55: =IF(J55="","",IF(J55="Conformidade",1,IF(J55="Não Conformidade",0,IF(J55="Não Conformidade Grave",-1,"")))) | O55: =IF(COUNTA(G55:J55)=0,"",ROUND(AVERAGE(K55:N55)*100,0)) | P55: =IFERROR(AVERAGEIF(C$2:C$201,C55,O$2:O$201),"N/A")
A56: =IF(B56="","",ROW()-1) | K56: =IF(G56="","",IF(G56="SIM",1,0)) | L56: =IF(H56="","",IF(H56="SIM",1,0)) | M56: =IF(I56="","",IF(I56="SIM",1,0)) | N56: =IF(J56="","",IF(J56="Conformidade",1,IF(J56="Não Conformidade",0,IF(J56="Não Conformidade Grave",-1,"")))) | O56: =IF(COUNTA(G56:J56)=0,"",ROUND(AVERAGE(K56:N56)*100,0)) | P56: =IFERROR(AVERAGEIF(C$2:C$201,C56,O$2:O$201),"N/A")
A57: =IF(B57="","",ROW()-1) | K57: =IF(G57="","",IF(G57="SIM",1,0)) | L57: =IF(H57="","",IF(H57="SIM",1,0)) | M57: =IF(I57="","",IF(I57="SIM",1,0)) | N57: =IF(J57="","",IF(J57="Conformidade",1,IF(J57="Não Conformidade",0,IF(J57="Não Conformidade Grave",-1,"")))) | O57: =IF(COUNTA(G57:J57)=0,"",ROUND(AVERAGE(K57:N57)*100,0)) | P57: =IFERROR(AVERAGEIF(C$2:C$201,C57,O$2:O$201),"N/A")
A58: =IF(B58="","",ROW()-1) | K58: =IF(G58="","",IF(G58="SIM",1,0)) | L58: =IF(H58="","",IF(H58="SIM",1,0)) | M58: =IF(I58="","",IF(I58="SIM",1,0)) | N58: =IF(J58="","",IF(J58="Conformidade",1,IF(J58="Não Conformidade",0,IF(J58="Não Conformidade Grave",-1,"")))) | O58: =IF(COUNTA(G58:J58)=0,"",ROUND(AVERAGE(K58:N58)*100,0)) | P58: =IFERROR(AVERAGEIF(C$2:C$201,C58,O$2:O$201),"N/A")
A59: =IF(B59="","",ROW()-1) | K59: =IF(G59="","",IF(G59="SIM",1,0)) | L59: =IF(H59="","",IF(H59="SIM",1,0)) | M59: =IF(I59="","",IF(I59="SIM",1,0)) | N59: =IF(J59="","",IF(J59="Conformidade",1,IF(J59="Não Conformidade",0,IF(J59="Não Conformidade Grave",-1,"")))) | O59: =IF(COUNTA(G59:J59)=0,"",ROUND(AVERAGE(K59:N59)*100,0)) | P59: =IFERROR(AVERAGEIF(C$2:C$201,C59,O$2:O$201),"N/A")
A60: =IF(B60="","",ROW()-1) | K60: =IF(G60="","",IF(G60="SIM",1,0)) | L60: =IF(H60="","",IF(H60="SIM",1,0)) | M60: =IF(I60="","",IF(I60="SIM",1,0)) | N60: =IF(J60="","",IF(J60="Conformidade",1,IF(J60="Não Conformidade",0,IF(J60="Não Conformidade Grave",-1,"")))) | O60: =IF(COUNTA(G60:J60)=0,"",ROUND(AVERAGE(K60:N60)*100,0)) | P60: =IFERROR(AVERAGEIF(C$2:C$201,C60,O$2:O$201),"N/A")
A61: =IF(B61="","",ROW()-1) | K61: =IF(G61="","",IF(G61="SIM",1,0)) | L61: =IF(H61="","",IF(H61="SIM",1,0)) | M61: =IF(I61="","",IF(I61="SIM",1,0)) | N61: =IF(J61="","",IF(J61="Conformidade",1,IF(J61="Não Conformidade",0,IF(J61="Não Conformidade Grave",-1,"")))) | O61: =IF(COUNTA(G61:J61)=0,"",ROUND(AVERAGE(K61:N61)*100,0)) | P61: =IFERROR(AVERAGEIF(C$2:C$201,C61,O$2:O$201),"N/A")
A62: =IF(B62="","",ROW()-1) | K62: =IF(G62="","",IF(G62="SIM",1,0)) | L62: =IF(H62="","",IF(H62="SIM",1,0)) | M62: =IF(I62="","",IF(I62="SIM",1,0)) | N62: =IF(J62="","",IF(J62="Conformidade",1,IF(J62="Não Conformidade",0,IF(J62="Não Conformidade Grave",-1,"")))) | O62: =IF(COUNTA(G62:J62)=0,"",ROUND(AVERAGE(K62:N62)*100,0)) | P62: =IFERROR(AVERAGEIF(C$2:C$201,C62,O$2:O$201),"N/A")
A63: =IF(B63="","",ROW()-1) | K63: =IF(G63="","",IF(G63="SIM",1,0)) | L63: =IF(H63="","",IF(H63="SIM",1,0)) | M63: =IF(I63="","",IF(I63="SIM",1,0)) | N63: =IF(J63="","",IF(J63="Conformidade",1,IF(J63="Não Conformidade",0,IF(J63="Não Conformidade Grave",-1,"")))) | O63: =IF(COUNTA(G63:J63)=0,"",ROUND(AVERAGE(K63:N63)*100,0)) | P63: =IFERROR(AVERAGEIF(C$2:C$201,C63,O$2:O$201),"N/A")
A64: =IF(B64="","",ROW()-1) | K64: =IF(G64="","",IF(G64="SIM",1,0)) | L64: =IF(H64="","",IF(H64="SIM",1,0)) | M64: =IF(I64="","",IF(I64="SIM",1,0)) | N64: =IF(J64="","",IF(J64="Conformidade",1,IF(J64="Não Conformidade",0,IF(J64="Não Conformidade Grave",-1,"")))) | O64: =IF(COUNTA(G64:J64)=0,"",ROUND(AVERAGE(K64:N64)*100,0)) | P64: =IFERROR(AVERAGEIF(C$2:C$201,C64,O$2:O$201),"N/A")
... A201: =IF(B201="","",ROW()-1) | K201: =IF(G201="","",IF(G201="SIM",1,0)) | L201: =IF(H201="","",IF(H201="SIM",1,0)) | M201: =IF(I201="","",IF(I201="SIM",1,0)) | N201: =IF(J201="","",IF(J201="Conformidade",1,IF(J201="Não Conformidade",0,IF(J201="Não Conformidade Grave",-1,"")))) | O201: =IF(COUNTA(G201:J201)=0,"",ROUND(AVERAGE(K201:N201)*100,0)) | P201: =IFERROR(AVERAGEIF(C$2:C$201,C201,O$2:O$201),"N/A")
A202: 1 | B202: 18/09/2026 | C202: Mobilize | D202: Treinamento | E202: Treinamento - Banco N1 | F202: 1 | G202: NÃO | H202: SIM | I202: NÃO | J202: Não Conformidade
A203: 2 | B203: 18/09/2026 | C203: Mobilize | D203: Treinamento | E203: Treinamento - Locadora N1 | F203: 1 | G203: NÃO | H203: SIM | I203: NÃO | J203: Não Conformidade
A204: 3 | B204: 18/09/2026 | C204: Mobilize | D204: Treinamento | E204: Treinamento - BackOffice N2 | F204: 1 | G204: SIM | H204: SIM | I204: NÃO | J204: Conformidade

Sheet Qualidade
A1: ID Avaliação | B1: Data da avaliação | C1: Operação | D1: Processo avaliado | E1: Processo Monitorado | F1: Quantidade | G1: Foram feitas monitorias de qualidade? | H1: Como são feitas as monitorias? | I1: Conforme? | J1: Existência | K1: Abrangência | L1: Conformidade | M1: Score Qualidade | N1: Geral | O1: Observação
A2: =IF(B2="","",ROW()-1) | B2: 46247 | C2: Financeiro | D2: Admissão | E2: Admissão | F2: 1 | G2: SIM | H2: Amostral | I2: Conformidade | J2: =IF(G2="","",IF(G2="SIM",1,0)) | K2: =IF(H2="","",IF(H2="Integral",1,IF(H2="Amostral",0.5,IF(H2="Não realizada",0,"")))) | L2: =IF(I2="","",IF(I2="Conformidade",1,IF(I2="Não Conformidade",0,IF(I2="Não Conformidade Grave",-1,"")))) | M2: =IF(COUNTA(G2:I2)=0,"",ROUND(AVERAGE(J2:L2)*100,0)) | N2: =IFERROR(AVERAGEIF(C$2:C$201,C2,M$2:M$201),"N/A") | O2: Linha de exemplo - substitua pelos dados reais
A3: =IF(B3="","",ROW()-1) | B3: 46180 | C3: Recursos Humanos | D3: Faturamento | E3: Faturamento | F3: 5 | G3: NÃO | H3: Não realizada | I3: Não Conformidade Grave | J3: =IF(G3="","",IF(G3="SIM",1,0)) | K3: =IF(H3="","",IF(H3="Integral",1,IF(H3="Amostral",0.5,IF(H3="Não realizada",0,"")))) | L3: =IF(I3="","",IF(I3="Conformidade",1,IF(I3="Não Conformidade",0,IF(I3="Não Conformidade Grave",-1,"")))) | M3: =IF(COUNTA(G3:I3)=0,"",ROUND(AVERAGE(J3:L3)*100,0)) | N3: =IFERROR(AVERAGEIF(C$2:C$201,C3,M$2:M$201),"N/A") | O3: Monitoria ainda não implantada; necessário definir rotina e amostra.
A4: =IF(B4="","",ROW()-1) | B4: 46211 | C4: Financeiro | D4: Gestão de Contratos | E4: Gestão de Contratos | F4: 6 | G4: SIM | H4: Amostral | I4: Conformidade | J4: =IF(G4="","",IF(G4="SIM",1,0)) | K4: =IF(H4="","",IF(H4="Integral",1,IF(H4="Amostral",0.5,IF(H4="Não realizada",0,"")))) | L4: =IF(I4="","",IF(I4="Conformidade",1,IF(I4="Não Conformidade",0,IF(I4="Não Conformidade Grave",-1,"")))) | M4: =IF(COUNTA(G4:I4)=0,"",ROUND(AVERAGE(J4:L4)*100,0)) | N4: =IFERROR(AVERAGEIF(C$2:C$201,C4,M$2:M$201),"N/A") | O4: Monitoria executada sem desvios relevantes.
A5: =IF(B5="","",ROW()-1) | B5: 46243 | C5: Atendimento | D5: Contas a Pagar | E5: Contas a Pagar | F5: 7 | G5: SIM | H5: Amostral | I5: Conformidade | J5: =IF(G5="","",IF(G5="SIM",1,0)) | K5: =IF(H5="","",IF(H5="Integral",1,IF(H5="Amostral",0.5,IF(H5="Não realizada",0,"")))) | L5: =IF(I5="","",IF(I5="Conformidade",1,IF(I5="Não Conformidade",0,IF(I5="Não Conformidade Grave",-1,"")))) | M5: =IF(COUNTA(G5:I5)=0,"",ROUND(AVERAGE(J5:L5)*100,0)) | N5: =IFERROR(AVERAGEIF(C$2:C$201,C5,M$2:M$201),"N/A") | O5: Monitoria executada sem desvios relevantes.
A6: =IF(B6="","",ROW()-1) | B6: 46183 | C6: Tecnologia | D6: Gestão de Incidentes | E6: Gestão de Incidentes | F6: 8 | G6: SIM | H6: Integral | I6: Conformidade | J6: =IF(G6="","",IF(G6="SIM",1,0)) | K6: =IF(H6="","",IF(H6="Integral",1,IF(H6="Amostral",0.5,IF(H6="Não realizada",0,"")))) | L6: =IF(I6="","",IF(I6="Conformidade",1,IF(I6="Não Conformidade",0,IF(I6="Não Conformidade Grave",-1,"")))) | M6: =IF(COUNTA(G6:I6)=0,"",ROUND(AVERAGE(J6:L6)*100,0)) | N6: =IFERROR(AVERAGEIF(C$2:C$201,C6,M$2:M$201),"N/A") | O6: Monitoria executada sem desvios relevantes.
A7: =IF(B7="","",ROW()-1) | B7: 46214 | C7: PROCESSOS | D7: Auditoria de Processos | E7: Auditoria de Processos | F7: 9 | G7: SIM | H7: Amostral | I7: Não Conformidade | J7: =IF(G7="","",IF(G7="SIM",1,0)) | K7: =IF(H7="","",IF(H7="Integral",1,IF(H7="Amostral",0.5,IF(H7="Não realizada",0,"")))) | L7: =IF(I7="","",IF(I7="Conformidade",1,IF(I7="Não Conformidade",0,IF(I7="Não Conformidade Grave",-1,"")))) | M7: =IF(COUNTA(G7:I7)=0,"",ROUND(AVERAGE(J7:L7)*100,0)) | N7: =IFERROR(AVERAGEIF(C$2:C$201,C7,M$2:M$201),"N/A") | O7: Monitoria identificou desvios que exigem tratamento.
A8: =IF(B8="","",ROW()-1) | B8: 46246 | C8: Qualidade | D8: Faturamento | E8: Faturamento | F8: 10 | G8: SIM | H8: Amostral | I8: Conformidade | J8: =IF(G8="","",IF(G8="SIM",1,0)) | K8: =IF(H8="","",IF(H8="Integral",1,IF(H8="Amostral",0.5,IF(H8="Não realizada",0,"")))) | L8: =IF(I8="","",IF(I8="Conformidade",1,IF(I8="Não Conformidade",0,IF(I8="Não Conformidade Grave",-1,"")))) | M8: =IF(COUNTA(G8:I8)=0,"",ROUND(AVERAGE(J8:L8)*100,0)) | N8: =IFERROR(AVERAGEIF(C$2:C$201,C8,M$2:M$201),"N/A") | O8: Monitoria executada sem desvios relevantes.
A9: =IF(B9="","",ROW()-1) | B9: 46186 | C9: Recursos Humanos | D9: Gestão de Contratos | E9: Gestão de Contratos | F9: 11 | G9: SIM | H9: Integral | I9: Conformidade | J9: =IF(G9="","",IF(G9="SIM",1,0)) | K9: =IF(H9="","",IF(H9="Integral",1,IF(H9="Amostral",0.5,IF(H9="Não realizada",0,"")))) | L9: =IF(I9="","",IF(I9="Conformidade",1,IF(I9="Não Conformidade",0,IF(I9="Não Conformidade Grave",-1,"")))) | M9: =IF(COUNTA(G9:I9)=0,"",ROUND(AVERAGE(J9:L9)*100,0)) | N9: =IFERROR(AVERAGEIF(C$2:C$201,C9,M$2:M$201),"N/A") | O9: Monitoria executada sem desvios relevantes.
A10: =IF(B10="","",ROW()-1) | B10: 46217 | C10: Financeiro | D10: Contas a Pagar | E10: Contas a Pagar | F10: 12 | G10: SIM | H10: Amostral | I10: Conformidade | J10: =IF(G10="","",IF(G10="SIM",1,0)) | K10: =IF(H10="","",IF(H10="Integral",1,IF(H10="Amostral",0.5,IF(H10="Não realizada",0,"")))) | L10: =IF(I10="","",IF(I10="Conformidade",1,IF(I10="Não Conformidade",0,IF(I10="Não Conformidade Grave",-1,"")))) | M10: =IF(COUNTA(G10:I10)=0,"",ROUND(AVERAGE(J10:L10)*100,0)) | N10: =IFERROR(AVERAGEIF(C$2:C$201,C10,M$2:M$201),"N/A") | O10: Monitoria executada sem desvios relevantes.
A11: =IF(B11="","",ROW()-1) | B11: 46249 | C11: Atendimento | D11: Gestão de Incidentes | E11: Gestão de Incidentes | F11: 13 | G11: NÃO | H11: Não realizada | I11: Não Conformidade | J11: =IF(G11="","",IF(G11="SIM",1,0)) | K11: =IF(H11="","",IF(H11="Integral",1,IF(H11="Amostral",0.5,IF(H11="Não realizada",0,"")))) | L11: =IF(I11="","",IF(I11="Conformidade",1,IF(I11="Não Conformidade",0,IF(I11="Não Conformidade Grave",-1,"")))) | M11: =IF(COUNTA(G11:I11)=0,"",ROUND(AVERAGE(J11:L11)*100,0)) | N11: =IFERROR(AVERAGEIF(C$2:C$201,C11,M$2:M$201),"N/A") | O11: Monitoria ainda não implantada; necessário definir rotina e amostra.
A12: =IF(B12="","",ROW()-1) | B12: 46189 | C12: Tecnologia | D12: Auditoria de Processos | E12: Auditoria de Processos | F12: 14 | G12: SIM | H12: Integral | I12: Conformidade | J12: =IF(G12="","",IF(G12="SIM",1,0)) | K12: =IF(H12="","",IF(H12="Integral",1,IF(H12="Amostral",0.5,IF(H12="Não realizada",0,"")))) | L12: =IF(I12="","",IF(I12="Conformidade",1,IF(I12="Não Conformidade",0,IF(I12="Não Conformidade Grave",-1,"")))) | M12: =IF(COUNTA(G12:I12)=0,"",ROUND(AVERAGE(J12:L12)*100,0)) | N12: =IFERROR(AVERAGEIF(C$2:C$201,C12,M$2:M$201),"N/A") | O12: Monitoria executada sem desvios relevantes.
A13: =IF(B13="","",ROW()-1) | B13: 46220 | C13: PROCESSOS | D13: Faturamento | E13: Faturamento | F13: 15 | G13: SIM | H13: Amostral | I13: Conformidade | J13: =IF(G13="","",IF(G13="SIM",1,0)) | K13: =IF(H13="","",IF(H13="Integral",1,IF(H13="Amostral",0.5,IF(H13="Não realizada",0,"")))) | L13: =IF(I13="","",IF(I13="Conformidade",1,IF(I13="Não Conformidade",0,IF(I13="Não Conformidade Grave",-1,"")))) | M13: =IF(COUNTA(G13:I13)=0,"",ROUND(AVERAGE(J13:L13)*100,0)) | N13: =IFERROR(AVERAGEIF(C$2:C$201,C13,M$2:M$201),"N/A") | O13: Monitoria executada sem desvios relevantes.
... A52: =IF(B52="","",ROW()-1) | B52: 46223 | C52: Financeiro | D52: Auditoria de Processos | E52: Auditoria de Processos | F52: 12 | G52: SIM | H52: Amostral | I52: Conformidade | J52: =IF(G52="","",IF(G52="SIM",1,0)) | K52: =IF(H52="","",IF(H52="Integral",1,IF(H52="Amostral",0.5,IF(H52="Não realizada",0,"")))) | L52: =IF(I52="","",IF(I52="Conformidade",1,IF(I52="Não Conformidade",0,IF(I52="Não Conformidade Grave",-1,"")))) | M52: =IF(COUNTA(G52:I52)=0,"",ROUND(AVERAGE(J52:L52)*100,0)) | N52: =IFERROR(AVERAGEIF(C$2:C$201,C52,M$2:M$201),"N/A") | O52: Monitoria executada sem desvios relevantes.
A53: =IF(B53="","",ROW()-1) | J53: =IF(G53="","",IF(G53="SIM",1,0)) | K53: =IF(H53="","",IF(H53="Integral",1,IF(H53="Amostral",0.5,IF(H53="Não realizada",0,"")))) | L53: =IF(I53="","",IF(I53="Conformidade",1,IF(I53="Não Conformidade",0,IF(I53="Não Conformidade Grave",-1,"")))) | M53: =IF(COUNTA(G53:I53)=0,"",ROUND(AVERAGE(J53:L53)*100,0)) | N53: =IFERROR(AVERAGEIF(C$2:C$201,C53,M$2:M$201),"N/A")
A54: =IF(B54="","",ROW()-1) | J54: =IF(G54="","",IF(G54="SIM",1,0)) | K54: =IF(H54="","",IF(H54="Integral",1,IF(H54="Amostral",0.5,IF(H54="Não realizada",0,"")))) | L54: =IF(I54="","",IF(I54="Conformidade",1,IF(I54="Não Conformidade",0,IF(I54="Não Conformidade Grave",-1,"")))) | M54: =IF(COUNTA(G54:I54)=0,"",ROUND(AVERAGE(J54:L54)*100,0)) | N54: =IFERROR(AVERAGEIF(C$2:C$201,C54,M$2:M$201),"N/A")
A55: =IF(B55="","",ROW()-1) | J55: =IF(G55="","",IF(G55="SIM",1,0)) | K55: =IF(H55="","",IF(H55="Integral",1,IF(H55="Amostral",0.5,IF(H55="Não realizada",0,"")))) | L55: =IF(I55="","",IF(I55="Conformidade",1,IF(I55="Não Conformidade",0,IF(I55="Não Conformidade Grave",-1,"")))) | M55: =IF(COUNTA(G55:I55)=0,"",ROUND(AVERAGE(J55:L55)*100,0)) | N55: =IFERROR(AVERAGEIF(C$2:C$201,C55,M$2:M$201),"N/A")
A56: =IF(B56="","",ROW()-1) | J56: =IF(G56="","",IF(G56="SIM",1,0)) | K56: =IF(H56="","",IF(H56="Integral",1,IF(H56="Amostral",0.5,IF(H56="Não realizada",0,"")))) | L56: =IF(I56="","",IF(I56="Conformidade",1,IF(I56="Não Conformidade",0,IF(I56="Não Conformidade Grave",-1,"")))) | M56: =IF(COUNTA(G56:I56)=0,"",ROUND(AVERAGE(J56:L56)*100,0)) | N56: =IFERROR(AVERAGEIF(C$2:C$201,C56,M$2:M$201),"N/A")
A57: =IF(B57="","",ROW()-1) | J57: =IF(G57="","",IF(G57="SIM",1,0)) | K57: =IF(H57="","",IF(H57="Integral",1,IF(H57="Amostral",0.5,IF(H57="Não realizada",0,"")))) | L57: =IF(I57="","",IF(I57="Conformidade",1,IF(I57="Não Conformidade",0,IF(I57="Não Conformidade Grave",-1,"")))) | M57: =IF(COUNTA(G57:I57)=0,"",ROUND(AVERAGE(J57:L57)*100,0)) | N57: =IFERROR(AVERAGEIF(C$2:C$201,C57,M$2:M$201),"N/A")
A58: =IF(B58="","",ROW()-1) | J58: =IF(G58="","",IF(G58="SIM",1,0)) | K58: =IF(H58="","",IF(H58="Integral",1,IF(H58="Amostral",0.5,IF(H58="Não realizada",0,"")))) | L58: =IF(I58="","",IF(I58="Conformidade",1,IF(I58="Não Conformidade",0,IF(I58="Não Conformidade Grave",-1,"")))) | M58: =IF(COUNTA(G58:I58)=0,"",ROUND(AVERAGE(J58:L58)*100,0)) | N58: =IFERROR(AVERAGEIF(C$2:C$201,C58,M$2:M$201),"N/A")
A59: =IF(B59="","",ROW()-1) | J59: =IF(G59="","",IF(G59="SIM",1,0)) | K59: =IF(H59="","",IF(H59="Integral",1,IF(H59="Amostral",0.5,IF(H59="Não realizada",0,"")))) | L59: =IF(I59="","",IF(I59="Conformidade",1,IF(I59="Não Conformidade",0,IF(I59="Não Conformidade Grave",-1,"")))) | M59: =IF(COUNTA(G59:I59)=0,"",ROUND(AVERAGE(J59:L59)*100,0)) | N59: =IFERROR(AVERAGEIF(C$2:C$201,C59,M$2:M$201),"N/A")
A60: =IF(B60="","",ROW()-1) | J60: =IF(G60="","",IF(G60="SIM",1,0)) | K60: =IF(H60="","",IF(H60="Integral",1,IF(H60="Amostral",0.5,IF(H60="Não realizada",0,"")))) | L60: =IF(I60="","",IF(I60="Conformidade",1,IF(I60="Não Conformidade",0,IF(I60="Não Conformidade Grave",-1,"")))) | M60: =IF(COUNTA(G60:I60)=0,"",ROUND(AVERAGE(J60:L60)*100,0)) | N60: =IFERROR(AVERAGEIF(C$2:C$201,C60,M$2:M$201),"N/A")
A61: =IF(B61="","",ROW()-1) | J61: =IF(G61="","",IF(G61="SIM",1,0)) | K61: =IF(H61="","",IF(H61="Integral",1,IF(H61="Amostral",0.5,IF(H61="Não realizada",0,"")))) | L61: =IF(I61="","",IF(I61="Conformidade",1,IF(I61="Não Conformidade",0,IF(I61="Não Conformidade Grave",-1,"")))) | M61: =IF(COUNTA(G61:I61)=0,"",ROUND(AVERAGE(J61:L61)*100,0)) | N61: =IFERROR(AVERAGEIF(C$2:C$201,C61,M$2:M$201),"N/A")
A62: =IF(B62="","",ROW()-1) | J62: =IF(G62="","",IF(G62="SIM",1,0)) | K62: =IF(H62="","",IF(H62="Integral",1,IF(H62="Amostral",0.5,IF(H62="Não realizada",0,"")))) | L62: =IF(I62="","",IF(I62="Conformidade",1,IF(I62="Não Conformidade",0,IF(I62="Não Conformidade Grave",-1,"")))) | M62: =IF(COUNTA(G62:I62)=0,"",ROUND(AVERAGE(J62:L62)*100,0)) | N62: =IFERROR(AVERAGEIF(C$2:C$201,C62,M$2:M$201),"N/A")
A63: =IF(B63="","",ROW()-1) | J63: =IF(G63="","",IF(G63="SIM",1,0)) | K63: =IF(H63="","",IF(H63="Integral",1,IF(H63="Amostral",0.5,IF(H63="Não realizada",0,"")))) | L63: =IF(I63="","",IF(I63="Conformidade",1,IF(I63="Não Conformidade",0,IF(I63="Não Conformidade Grave",-1,"")))) | M63: =IF(COUNTA(G63:I63)=0,"",ROUND(AVERAGE(J63:L63)*100,0)) | N63: =IFERROR(AVERAGEIF(C$2:C$201,C63,M$2:M$201),"N/A")
